<mujoco model="robotic_arm_with_black_links">
    <visual>
        <headlight ambient="0.5 0.5 0.5" />
    </visual>

    <asset>
        <material name="black" rgba="0 0 0 1" />
        <material name="green" rgba="0 1 0 1" />
        <material name="blue" rgba="0 0 1 1" />
        <material name="red" rgba="1 0 0 1" />
        <material name="purple" rgba="0.5 0 0.5 1" />
        <material name="white" rgba="1 1 1 1" />
    </asset>

    <option gravity="0 0 -9.81" />

    <worldbody>
        <light diffuse=".5 .5 .5" pos="0 0 3" dir="0 0 -1"/>
        <geom type="plane" size="10 10 0.1" material="blue"/>

        <body name="base" pos="0 0 0.1">
            <geom type="box" size="0.1 0.1 0.2" rgba="0 0 0 0.5" />

            <!-- Smaller Base on Corner of Main Base -->
            <body name="smaller_base" pos="0.03 0.0455 0.255">
                <geom type="box" size="0.075 0.055 0.055" rgba="0 0 0 0.5" />

                <!-- Shoulder Pitch -->
                <body name="shoulder_pitch" pos="0.0789 -0.0745 0" euler="0 90 0">
                    <joint name="shoulder_pitch_joint" type="hinge" axis="0 0 1" pos="0 0 0" />
                    <geom type="cylinder" size="0.0198 0.0115" rgba="0 0 0 0.5" mass="0.065"/>

                    <!-- Shoulder Roll -->
                    <body name="shoulder_roll" pos="0 0 0.0311" euler="0 90 0">
                        <joint name="shoulder_roll_joint" type="hinge" axis="0 0 1" pos="0 0 0" range="0 180"/> 
                        <geom type="cylinder" size="0.0198 0.0115" rgba="0 0 0 0.5" mass="0.065"/>

                        <!-- Shoulder Yaw -->
                        <body name="shoulder_yaw" pos="0 0.031 0" euler="90 0 0">
                            <joint name="shoulder_yaw_joint" type="hinge" axis="0 0 1" pos="0 0 0" />
                            <geom type="cylinder" size="0.0198 0.0115" rgba="0 0 0 0.5"  mass="0.065"/>

                            <!-- Green Link 1 -->
                            <body name="link1" pos="0 0 -0.110"  euler="0 90 0">
                                <geom type="box" size="0.1 0.011 0.01" material="green" mass="0.02" contype="0" conaffinity="0"/>

                                <!-- Elbow Pitch -->
                                <body name="elbow_pitch" pos="0.101 0 0" euler="0 0 90">
                                    <joint name="elbow_pitch_joint" type="hinge" axis="0 0 1" pos="0 0 0" />
                                    <geom type="cylinder" size="0.0198 0.0115" rgba="0 0 0 0.5" mass="0.065" contype="0" conaffinity="0"/>

                                    <body name="end_effector" pos="0 -0.111 0"  euler="0 0 90">
                                        <geom type="box" size="0.1 0.01 0.01" material="purple" contype="0" conaffinity="0"/>
                                        <geom type="sphere" size="0.03" pos="-0.1 0 -0" material="red" contype="0" conaffinity="0"/>
                                    </body>
                                </body>
                            </body>
                        </body>
                    </body>
                </body>
            </body>
        </body>
    </worldbody>

    <actuator>
        <motor name="shoulder_pitch_motor" joint="shoulder_pitch_joint" gear="100"/>
        <motor name="shoulder_roll_motor" joint="shoulder_roll_joint" gear="100"/>
        <motor name="shoulder_yaw_motor" joint="shoulder_yaw_joint" gear="100"/>
        <motor name="elbow_pitch_motor" joint="elbow_pitch_joint" gear="100"/>
    </actuator>
</mujoco>
